<?xml version="1.0" ?>
<robot name="turtlebot3_burger" xmlns:xacro="http://ros.org/wiki/xacro">
	<xacro:include filename="$(find turtlebot3_description)/urdf/common_properties.xacro"/>

	<link name="base_footprint"/>

	<joint name="base_joint" type="fixed">
		<parent link="base_footprint"/>
		<child link="base_link"/>
		<origin xyz="0 0 0.010" rpy="0 0 0"/>
	</joint>

	<link name="base_link">
		<visual>
			<origin xyz="-0.225 0.225 0.03" rpy="1.57 0 0"/>
			<geometry>
				<mesh filename="package://turtlebot3_description/meshes/base/body.STL" scale="0.001 0.001 0.001"/>
			</geometry>
			<material name="white"/>
		</visual>

		<collision>
			<origin xyz="0 0 0.14" rpy="0 0 0"/>
			<geometry>
				<box size="0.45 0.45 0.22"/>
			</geometry>
		</collision>
	</link>

  	<joint name="wheel_left_joint" type="continuous">
    	<parent link="base_link"/>
    	<child link="wheel_left_link"/>
    	<origin xyz="0.0 0.165 0.0625" rpy="-1.57 0 0"/>
    	<axis xyz="0 0 1"/>
  	</joint>

	<link name="wheel_left_link">
		<visual>
			<origin xyz="0.0775 -0.0775 -0.0235" rpy="0 0 1.57"/>
			<geometry>
				<mesh filename="package://turtlebot3_description/meshes/wheels/left_wheel.STL" scale="0.001 0.001 0.001"/>
			</geometry>
			<material name="black"/>
		</visual>

		<collision>
			<origin xyz="0 0 0" rpy="0 0 0"/>
			<geometry>
				<cylinder length="0.047" radius="0.0775"/>
			</geometry>
		</collision>
	</link>

	<joint name="wheel_right_joint" type="continuous">
		<parent link="base_link"/>
		<child link="wheel_right_link"/>
		<origin xyz="0.0 -0.165 0.0625" rpy="-1.57 0 0"/>
		<axis xyz="0 0 1"/>
	</joint>

	<link name="wheel_right_link">
		<visual>
			<origin xyz="0.0775 -0.0775 -0.0235" rpy="0 0 1.57"/>
			<geometry>
				<mesh filename="package://turtlebot3_description/meshes/wheels/right_wheel.STL" scale="0.001 0.001 0.001"/>
			</geometry>
			<material name="black"/>
		</visual>

		<collision>
			<origin xyz="0 0 0" rpy="0 0 0"/>
			<geometry>
				<cylinder length="0.047" radius="0.0775"/>
			</geometry>
		</collision>
	</link>

	<joint name="imu_joint" type="fixed">
		<parent link="base_link"/>
		<child link="imu_link"/>
		<origin xyz="0 0 0.09" rpy="0 0 0"/>
	</joint>

	<link name="imu_link">
		<visual>
			<origin xyz="-0.051 -0.0375 0" rpy="0 0 0"/>
			<geometry>
				<mesh filename="package://turtlebot3_description/meshes/sensors/opencr.STL" scale="0.001 0.001 0.001"/>
			</geometry>
			<material name="blue"/>
		</visual>
	</link>


	<joint name="scan_joint" type="fixed">
		<parent link="base_link"/>
		<child link="base_scan"/>
		<origin xyz="0 0 0.2025"/>
	</joint>

	<link name="base_scan">
		<visual>
			<origin xyz="0 0 0" rpy="0 0 0"/>
			<geometry>
				<mesh filename="package://turtlebot3_description/meshes/sensors/lds.stl" scale="0.001 0.001 0.001"/>
			</geometry>
			<material name="blue"/>
		</visual>
	</link>

</robot>